<?xml version="1.0"?>
<robot xmlns:xacro="http://www.ros.org/wiki/xacro" name="sentinel">
    <xacro:include filename="$(find sentinel_description)/urdf/base.xacro"/>
    <xacro:include filename="$(find sentinel_description)/urdf/macanum_wheel.xacro"/>
    <xacro:include filename="$(find sentinel_description)/urdf/sensors.xacro"/>
    
    
    <xacro:base/>
    <xacro:macanum_wheel prefix="top_right"/>
    <xacro:macanum_wheel prefix="top_left"/>
    <xacro:macanum_wheel prefix="lower_right"/>
    <xacro:macanum_wheel prefix="lower_left"/>
    <xacro:rplidar/>

    <link name="base_footprint">
        
    </link>

    <joint name="joint_name" type="fixed">
        <parent link="base_footprint"/>
        <child link="base_link"/>
        <origin xyz="0.0 0.0 0.04" rpy="0.0 0.0 0.0"/>
    </joint>
    

    <joint name="top_right_wheel_joint" type="continuous">
        <parent link="base_link"/>
        <child link="top_right_wheel"/>
        <axis xyz="0 0 1"/>
        <origin xyz="0.105 -0.125 -0.01" rpy="-1.57079632679  0 0"/>
    </joint>

    <joint name="top_left_wheel_joint" type="continuous">
        <parent link="base_link"/>
        <child link="top_left_wheel"/>
        <axis xyz="0 0 1"/>
        <origin xyz="0.105 0.125 -0.01" rpy="-1.57079632679  0 0"/>
    </joint>

    <joint name="lower_right_wheel_joint" type="continuous">
        <parent link="base_link"/>
        <child link="lower_right_wheel"/>
        <axis xyz="0 0 1"/>
        <origin xyz="-0.105 -0.125 -0.01" rpy="-1.57079632679  0 0"/>
    </joint>

    <joint name="lower_left_wheel_joint" type="continuous">
        <parent link="base_link"/>
        <child link="lower_left_wheel"/>
        <axis xyz="0 0 1"/>
        <origin xyz="-0.105 0.125 -0.01" rpy="-1.57079632679  0 0"/>
    </joint>

    <joint name="lidar_name" type="fixed">
        <parent link="base_link"/>
        <child link="laser"/>
        <origin xyz="0.1207 0.0 0.055" rpy="0.0 0.0 3.14159265359"/>
    </joint>
</robot>